<?xml version="1.0" encoding="utf-8"?>
<robot name="rover" xmlns:xacro="http://www.ros.org/wiki/xacro">
	<link name="rover_rear_left_wheel">
	    	<inertial>
	      		<origin xyz="-2.59351787823547E-08 0.0469989024569845 3.79124059923797E-09" rpy="0 0 0" />
	      		<mass value="1.00439993070027" />
	      		<inertia
				ixx="0.000345151605779146"
				ixy="2.78564078444317E-11"
				ixz="6.00001095471038E-12"
				iyy="0.000496032321995572"
				iyz="-3.01089550238534E-11"
				izz="0.000345150327522887" />
	    	</inertial>
	    	<visual>
	      		<origin xyz="0 0 0" rpy="0 0 0" />
	      		<geometry>
	      			<mesh filename="package://rover_description/meshes/rover_rear_left_wheel.STL" />
	     		</geometry>
	      		<material name="Green">
				<color rgba="0.0 1.0 0.0 1.0"/>
			</material>
	    	</visual>
	    	<collision>
	      		<origin xyz="0 0 0" rpy="0 0 0" />
	      		<geometry> 
	      			<mesh filename="package://rover_description/meshes/rover_rear_left_wheel.STL" />
	      		</geometry>
	    	</collision>
	</link>
	
	<link name="rear_left_wheel">
		<visual>
			<origin xyz="0 0 0" rpy="${PI/2} 0 0" />
			<geometry>
				<cylinder length="${wheel_width}" radius="${wheel_radius}"/>
			</geometry>
			<material name="Green" />
		</visual>
		<collision>
			<origin xyz="0 0 0" rpy="${PI/2} 0 0" />
			<geometry>
				<cylinder length="${wheel_width}" radius="${wheel_radius}"/>
			</geometry>
		</collision>
	</link>

	<joint name="rear_left_wheel_to_rover_rear_left_wheel" type="fixed">
		<origin xyz="0 0 0" rpy="0 0 0" />
		<parent link="rear_left_wheel" />
		<child link="rover_rear_left_wheel" />
	</joint>

	<joint name="rear_left_wheel_to_base" type="continuous">
	    	<origin xyz="-0.0599999999999999 0.1135 -0.0240000000000001" rpy="0 0 0" />
	    	<parent link="base_link" />
	    	<child link="rear_left_wheel" />
	    	<axis xyz="0 -1 0" />
	</joint>
</robot>
