<?xml version="1.0" encoding="utf-8"?>
<robot name="rover" xmlns:xacro="http://www.ros.org/wiki/xacro">
	<link name="rover_rear_right_wheel">
		<inertial>
	      		<origin xyz="-3.07806621857587E-08 0.000644885679501911 -1.07149003419904E-08" rpy="0 0 0" />
	   		<mass value="0.502189683316104" />
 			<inertia
				ixx="0.000172572066971779"
				ixy="3.12843459192034E-11"
				ixz="-8.28069308806327E-11"
				iyy="0.00024800975238356"
				iyz="-3.42119671011516E-11"
				izz="0.000172572175204211" />
	    	</inertial>
	    	<visual>
	      		<origin xyz="0 0 0" rpy="0 0 0" />
	      		<geometry>
				<mesh filename="package://rover_description/meshes/rover_rear_right_wheel.STL" />
	      		</geometry>
		      	<material name="Green">
				<color rgba="0.0 1.0 0.0 1.0"/>
			</material>
	    	</visual>
	    	<collision>
	      		<origin xyz="0 0 0" rpy="0 0 0" />
	      		<geometry>
				<mesh filename="package://rover_description/meshes/rover_rear_right_wheel.STL" />
	      		</geometry>
	    	</collision>
	</link>

	<link name="rear_right_wheel">
		<visual>
			<origin xyz="0 0 0" rpy="${PI/2} 0 0" />
			<geometry>
				<cylinder length="${wheel_width}" radius="${wheel_radius}"/>
			</geometry>
			<material name="Green" />
		</visual>
		<collision>
			<origin xyz="0 0 0" rpy="${PI/2} 0 0" />
			<geometry>
				<cylinder length="${wheel_width}" radius="${wheel_radius}"/>
			</geometry>
		</collision>
	</link>

	<joint name="rear_right_wheel_to_rover_rear_right_wheel" type="fixed">
		<origin xyz="0 0 0" rpy="0 0 0" />
		<parent link="rear_right_wheel" />
		<child link="rover_rear_right_wheel" />
	</joint>

  	<joint name="rear_right_wheel_to_base" type="continuous">
	    <origin xyz="-0.0600000000000001 -0.1135 -0.024" rpy="0 0 0" />
	    <parent link="base_link" />
	    <child link="rear_right_wheel" />
	    <axis xyz="0 1 0" />
	</joint>
</robot>
