<?xml version="1.0" encoding="utf-8"?>
<robot name="rover" xmlns:xacro="http://www.ros.org/wiki/xacro">
	<link name="rover_front_right_wheel">
    		<inertial>
		      	<origin xyz="-1.70667308341255E-08 -0.0469989024632745 -1.98932720574252E-08" rpy="0 0 0" />
		      	<mass value="1.0043999304589" />
		      	<inertia
				ixx="0.000345151708823498"
				ixy="-1.23016049736541E-12"
				ixz="-1.34409459667581E-11"
				iyy="0.00049603232185964"
				iyz="-4.10008104838091E-11"
				izz="0.000345150224335857" />
		</inertial>
		<visual>
		      	<origin xyz="0 0 0" rpy="0 0 0" />
		      	<geometry>
				<mesh filename="package://rover_description/meshes/rover_front_right_wheel.STL" />
		      	</geometry>
		      	<material name="Green">
				<color rgba="0.0 1.0 0.0 1.0"/>
			</material>
		</visual>
		<collision>
		      	<origin xyz="0 0 0" rpy="0 0 0" />
		      	<geometry>
				<mesh filename="package://rover_description/meshes/rover_front_right_wheel.STL" />
		     	</geometry>
		</collision>
	</link>

	<link name="front_right_wheel">
		<visual>
			<origin xyz="0 0 0" rpy="${PI/2} 0 0" />
			<geometry>
				<cylinder length="${wheel_width}" radius="${wheel_radius}"/>
			</geometry>
			<material name="Green" />
		</visual>
		<collision>
			<origin xyz="0 0 0" rpy="${PI/2} 0 0" />
			<geometry>
				<cylinder length="${wheel_width}" radius="${wheel_radius}"/>
			</geometry>
		</collision>
	</link>

	<joint name="front_right_wheel_to_rover_front_right_wheel" type="fixed">
		<origin xyz="0 0 0" rpy="0 0 0" />
		<parent link="front_right_wheel" />
		<child link="rover_front_right_wheel" />
	</joint>

	<joint name="front_right_wheel_to_base" type="continuous">
		<origin xyz="0.0599999999999999 -0.1135 -0.024" rpy="0 0 0" />
		<parent link="rover_base" />
		<child link="front_right_wheel" />
		<axis xyz="0 1 0" />
	</joint>
</robot>
